Workbook

Sheet Summary
A2: SIT Daily Status Display Hub Development Sprint 5.1 & Sprint 5.2 | E2: Day 4 | F2: =TODAY() -> 46136
A5: ORIGINAL | C5: REVISED
A6: Start | B6: End | C6: Start | D6: End
A7: 46062 | B7: 46066
A10: Overall Status: | B10: GREEN
A11: Total TC's | B11: PLAN TO DATE | E11: ACTUAL EXECUTION TO DATE | L11: Actual vs Planned Executed %
B12: Plan Executed TC's | C12: Execution Rate (%) | D12: Pass Rate (%) | E12: Executed TC's | F12: Passed | G12: Failed | H12: NA | I12: Blocked | J12: Execution Rate (%) | K12: Pass Rate (%)
A13: =J35 -> 20 | B13: 20 | C13: =B13/A13 -> 1 | D13: 0 | E13: =K35 -> 17 | F13: =L35 -> 17 | G13: =M35 -> 0 | H13: =N35 -> 0 | I13: =O35 -> 0 | J13: =E13/A13 -> 0.85 | K13: =(F13+H13)/E13 -> 1 | L13: =J13/C13 -> 0.85
A16: DEFECT PENETRATION
A17: Total Defect | B17: Penetration Rate (%) | C17: Critical | D17: High | E17: Medium | F17: Low
A18: 0 | B18: =A18/E13 -> 0 | C18: 0 | D18: 0 | E18: 0 | F18: 0
A21: Executive Summary
A22: Day 2 Internal Test no defect
A28: Test Case
A30: No | B30: Sprint | C30: Ticket Story | E30: Module | G30: Platform | H30: Testing Start | I30: Testing End | J30: Total TCs | K30: TC Run | L30: TC Passed | M30: TC Failed | N30: TC NA | O30: TC Blocked | P30: TC Not Tested | Q30: Remark | T30: Status
A31: 1 | B31: Sprint 5.1 | C31: https://snpgroup.atlassian.net/browse/SPPAT-1724 | E31: As an Global Admin, and Super Admin I can view the product industry list so that I can manage and monitor all available master data efficiently | G31: Web CMS | H31: 46062 | I31: 46066 | J31: =COUNTIF('Global Admin'!E:E, E31) -> 6 | K31: =SUM(L31:O31) -> 6 | L31: =COUNTIFS('Global Admin'!E:E, E31,'Global Admin'!R:R, "Passed") -> 6 | M31: =COUNTIFS('Global Admin'!E:E,E31,'Global Admin'!R:R, "Failed") -> 0 | N31: =COUNTIFS('Global Admin'!E:E, E31,'Global Admin'!R:R, "NA") -> 0 | O31: =COUNTIFS('Global Admin'!E:E, E31,'Global Admin'!R:R, "Blocked") -> 0 | P31: =COUNTIFS('Global Admin'!F:F, E31,'Global Admin'!S:S, "Not Tested") -> 0
A32: 2 | B32: Sprint 5.1 | C32: https://snpgroup.atlassian.net/browse/SPPAT-1725 | E32: As an Global Admin and Super Admin, I can create Industries, Categories, and Sub-Categories data on the form field page when the data I am searching for is not found | G32: Web CMS | H32: 46062 | I32: 46066 | J32: =COUNTIF('Global Admin'!E:E, E32) -> 4 | K32: =SUM(L32:O32) -> 3 | L32: =COUNTIFS('Global Admin'!E:E, E32,'Global Admin'!R:R, "Passed") -> 3 | M32: =COUNTIFS('Global Admin'!E:E,E32,'Global Admin'!R:R, "Failed") -> 0 | N32: =COUNTIFS('Global Admin'!E:E, E32,'Global Admin'!R:R, "NA") -> 0 | O32: =COUNTIFS('Global Admin'!E:E, E32,'Global Admin'!R:R, "Blocked") -> 0 | P32: =COUNTIFS('Global Admin'!F:F, E32,'Global Admin'!S:S, "Not Tested") -> 0
A33: 11 | B33: Sprint 5.1 | C33: https://snpgroup.atlassian.net/browse/SPPAT-1741 | E33: As an Global Admin, Super Admin, PIC Organization, I can view the list of user management data so that I can monitor and manage user information effectively | G33: Web CMS | H33: 46062 | I33: 46066 | J33: =COUNTIF('PIC Organization'!E:E, E33) -> 4 | K33: =SUM(L33:O33) -> 3 | L33: =COUNTIFS('PIC Organization'!E:E, E33,'PIC Organization'!R:R, "Passed") -> 3 | M33: =COUNTIFS('PIC Organization'!E:E,E33,'PIC Organization'!R:R, "Failed") -> 0 | N33: =COUNTIFS('PIC Organization'!E:E, E33,'PIC Organization'!R:R, "NA") -> 0 | O33: =COUNTIFS('PIC Organization'!E:E, E33,'PIC Organization'!R:R, "Blocked") -> 0 | P33: =COUNTIFS('PIC Organization'!F:F, E33,'PIC Organization'!S:S, "Not Tested") -> 0
A34: 12 | B34: Sprint 5.1 | C34: https://snpgroup.atlassian.net/browse/SPPAT-1748 | E34: As an Global Admin, Super Admin and PIC Organization, I can create new user management data so that I can register and manage user information within the system | G34: Web CMS | H34: 46062 | I34: 46066 | J34: =COUNTIF('PIC Organization'!E:E, E34) -> 6 | K34: =SUM(L34:O34) -> 5 | L34: =COUNTIFS('PIC Organization'!E:E, E34,'PIC Organization'!R:R, "Passed") -> 5 | M34: =COUNTIFS('PIC Organization'!E:E,E34,'PIC Organization'!R:R, "Failed") -> 0 | N34: =COUNTIFS('PIC Organization'!E:E, E34,'PIC Organization'!R:R, "NA") -> 0 | O34: =COUNTIFS('PIC Organization'!E:E, E34,'PIC Organization'!R:R, "Blocked") -> 0 | P34: =COUNTIFS('PIC Organization'!F:F, E34,'PIC Organization'!S:S, "Not Tested") -> 0
I35: TOTAL | J35: =SUM(J31:J34) -> 20 | K35: =SUM(K31:K34) -> 17 | L35: =SUM(L31:L34) -> 17 | M35: =SUM(M31:M34) -> 0 | N35: =SUM(N31:N34) -> 0 | O35: =SUM(O31:O34) -> 0 | P35: =SUM(P31:P34) -> 0
J36: Total TCs | K36: TC Run | L36: TC Passed | M36: TC Failed | N36: TC NA | O36: TC Blocked | P36: TC Not Tested
A38: Open Defects
A40: No. | B40: ID / Ticket JIRA | D40: Error Description | F40: Test Case | G40: Impacted Test Cases | H40: Severity | I40: Status | J40: PIC (FE/BE/Mobile) | K40: Raised Date | L40: ETA | M40: Aging
A43: NOTE
A44: DEFECT STATUS ONLY CAN BE CLOSED UNTIL RETEST COMPLETED AND RESULT VALIDATED BY TOWER OR BUSINESS USER
A46: Execution Details
A48: DAY | B48: Total TCs | C48: 1331
B49: Per Day | K49: Accumulated (Total)
B50: Execution Date | C50: Plan Execution | D50: Plan Passed | E50: Recovery Plan | F50: Recovery Pass | G50: Passed | H50: Failed | I50: NA | J50: Blocked | K50: Plan Execution | L50: % Plan Execution | M50: Plan Passed | N50: % Plan Passed | O50: Actual | P50: % Actual | Q50: Passed | R50: Failed | S50: NA | T50: Blocked | U50: Remaining
A51: 1 | B51: 46133 | C51: 120 | D51: 120 | E51: 0 | F51: 0 | G51: 120 | H51: 0 | I51: 0 | J51: 0 | K51: =C51 -> 120 | L51: =K51/$C$48 -> 0.090157776 | M51: =D51 -> 120 | N51: =M51/$C$48 -> 0.090157776 | O51: =SUM(G51:J51) -> 120 | P51: =O51/$C$48 -> 0.090157776 | Q51: =G51 -> 120 | R51: =H51 -> 0 | S51: =I51 -> 0 | T51: =J51 -> 0 | U51: =$C$48-O51 -> 1211
A52: 2 | B52: 46134 | C52: 112 | D52: 112 | E52: 0 | F52: 0 | G52: 112 | H52: 0 | I52: 0 | J52: 0 | K52: =C51+C52 -> 232 | L52: =K52/$C$48 -> 0.17430503 | M52: =SUM(D51:D52) -> 232 | N52: =M52/$C$48 -> 0.17430503 | O52: =IF(AND(B51>=TODAY(),ISBLANK(G52)=TRUE()),0,O51+G52+H52+I52) -> 232 | P52: =O52/$C$48 -> 0.17430503 | Q52: =IF(AND(B51>=TODAY(),OR(ISBLANK(G52)=TRUE(),G52=0)),0,Q51+G52) -> 232 | R52: =IF(AND(B51>=TODAY(),OR(ISBLANK(H52)=TRUE(),H52=0)),0,R51+H52) -> 0 | S52: =I52 -> 0 | T52: =J52 -> 0 | U52: =$C$48-O52 -> 1099
A53: 3 | B53: 46135 | C53: 108 | D53: 108 | E53: 0 | F53: 0 | G53: 108 | H53: 0 | I53: 0 | J53: 0 | K53: =SUM(C51:C53) -> 340 | L53: =K53/$C$48 -> 0.25544703 | M53: =SUM(D51:D53) -> 340 | N53: =M53/$C$48 -> 0.25544703 | O53: =IF(AND(B52>=TODAY(),ISBLANK(G53)=TRUE()),0,O52+G53+H53+I53) -> 340 | P53: =O53/$C$48 -> 0.25544703 | Q53: =IF(AND(B52>=TODAY(),OR(ISBLANK(G53)=TRUE(),G53=0)),0,Q52+G53) -> 340 | R53: =IF(AND(B52>=TODAY(),OR(ISBLANK(H53)=TRUE(),H53=0)),0,R52+H53) -> 0 | S53: =I53 -> 0 | T53: =J53 -> 0 | U53: =$C$48-O53 -> 991
A54: 4 | B54: 46136 | C54: 45 | D54: 45 | E54: 0 | F54: 0 | G54: 45 | H54: 0 | I54: 0 | J54: 0 | K54: =SUM(C52:C54) -> 265 | L54: =K54/$C$48 -> 0.19909842 | M54: =SUM(D52:D54) -> 265 | N54: =M54/$C$48 -> 0.19909842 | O54: =IF(AND(B53>=TODAY(),ISBLANK(G54)=TRUE()),0,O53+G54+H54+I54) -> 385 | P54: =O54/$C$48 -> 0.2892562 | Q54: =IF(AND(B53>=TODAY(),OR(ISBLANK(G54)=TRUE(),G54=0)),0,Q53+G54) -> 385 | R54: =IF(AND(B53>=TODAY(),OR(ISBLANK(H54)=TRUE(),H54=0)),0,R53+H54) -> 0 | S54: =I54 -> 0 | T54: =J54 -> 0 | U54: =$C$48-O54 -> 946
A55: 5 | B55: 46139 | C55: 0 | D55: 0 | E55: 0 | F55: 0 | G55: 0 | H55: 0 | I55: 0 | J55: 0 | K55: =SUM(C53:C55) -> 153 | L55: =K55/$C$48 -> 0.11495116 | M55: =SUM(D53:D55) -> 153 | N55: =M55/$C$48 -> 0.11495116 | O55: =IF(AND(B54>=TODAY(),ISBLANK(G55)=TRUE()),0,O54+G55+H55+I55) -> 385 | P55: =O55/$C$48 -> 0.2892562 | Q55: =IF(AND(B54>=TODAY(),OR(ISBLANK(G55)=TRUE(),G55=0)),0,Q54+G55) -> 0 | R55: =IF(AND(B54>=TODAY(),OR(ISBLANK(H55)=TRUE(),H55=0)),0,R54+H55) -> 0 | S55: =I55 -> 0 | T55: =J55 -> 0 | U55: =$C$48-O55 -> 946
C56: =SUM(C51:C55) -> 385 | D56: =SUM(D51:D55) -> 385 | E56: =SUM(E51:E55) -> 0 | F56: =SUM(F51:F55) -> 0 | G56: =SUM(G51:G55) -> 385 | H56: =SUM(H51:H55) -> 0 | I56: =SUM(I51:I55) -> 0 | J56: =SUM(J51:J55) -> 0
D57: Passed+NA= | E57: =G56+I56 -> 385
D58: Passed+Failed+NA= | E58: =SUM(G56:I56) -> 385
D59: Pass Rate= | E59: =E57/E58 -> 1
B62: DO NOT CHANGE THE FORMULA
A64: PROJECT STATUS
...

Sheet Global Admin
A1: NO | B1: SPRINT | C1: TC_ID | D1: LINK STORY | E1: FEATURE / SUITE | F1: ROLE USER | G1: PLATFORM | H1: TEST CASE | I1: PRECONDITIONS | J1: STEPS | K1: DATA | L1: EXPECTED | M1: BEHAVIOUR | N1: PRIORITY | O1: SEVERITY | P1: COMPLEXITY | Q1: TYPE | R1: ACTUAL RESULT | S1: REMARKS | T1: DATE | U1: PIC TESTER | V1: EVIDENCE SIT | W1: Evidence Internal Test | X1: Automate/Manual
A2: =ROW(A1) -> 1 | B2: Sprint 5.1 | C2: TC ID - 06 | D2: https://snpgroup.atlassian.net/browse/SPPAT-1724 | E2: As an Global Admin, and Super Admin I can view the product industry list so that I can manage and monitor all available master data efficiently | F2: Global Admin | G2: Web CMS | H2: Global admin can search data Product Industry | I2: * User already login as Global Admin * User opened Product Industry page | J2: * Input character on search column * Press button Enter from keyboard | K2: rules : * must press enter button from keyboard * min 3 character for search * can input for example SABUN, Sabun, SAbun, sabun (not case sensitive) | L2: * Success input character * Success show the result | M2: Positive | N2: High | O2: Normal | P2: Medium | Q2: Functional | R2: Passed | T2: 46133 | U2: Miftha
A3: =ROW(A2) -> 2 | B3: Sprint 5.1 | C3: TC ID - 07 | D3: https://snpgroup.atlassian.net/browse/SPPAT-1724 | E3: As an Global Admin, and Super Admin I can view the product industry list so that I can manage and monitor all available master data efficiently | F3: Global Admin | G3: Web CMS | H3: Global admin input character on column search less than 3 character | I3: * Already login as Global Admin * Already on Product Industry page | J3: * Input less than 3 character on column search * Press enter button on your keyboard | K3: Example : * Have keyword SABUN and then input character only S or S.A on column search | L3: Cannot search the keyword with less than 3 character and the result cannot shown | M3: Negative | N3: Medium | O3: Normal | P3: Medium | Q3: Functional | R3: Passed | T3: 46133 | U3: Miftha
A4: =ROW(A3) -> 3 | B4: Sprint 5.1 | C4: TC ID - 08 | D4: https://snpgroup.atlassian.net/browse/SPPAT-1724 | E4: As an Global Admin, and Super Admin I can view the product industry list so that I can manage and monitor all available master data efficiently | F4: Global Admin | G4: Web CMS | H4: Global Admin can filter on dropdown field | I4: * Already login as Global Admin * Already on Product Industry page | J4: * Click filter dropdown beside search column * Select the option based on list | K4: * - * - | L4: * Open the dropdown and show the list on dropdown * Success selected option and show result based on filter | M4: Positive | N4: High | O4: Normal | P4: Medium | Q4: Functional | R4: Passed | T4: 46133 | U4: Miftha
A5: =ROW(A4) -> 4 | B5: Sprint 5.1 | C5: TC ID - 09 | D5: https://snpgroup.atlassian.net/browse/SPPAT-1724 | E5: As an Global Admin, and Super Admin I can view the product industry list so that I can manage and monitor all available master data efficiently | F5: Global Admin | G5: Web CMS | H5: Global admin can't search data Product Industry | I5: * User already login as Global Admin * User opened Product Industry page | J5: * Input character on search column with invalid data * Press button Enter from keyboard | K5: * example : 1@!&%&*! | L5: * Success input character * Success show the result data not found * Success showed snackbar "Industry search term contains invalid characters" | M5: Negative | N5: Medium | O5: Normal | P5: Medium | Q5: Functional | R5: Passed | S5: 1@@!#$@ -> "Industry search term contains invalid characters" 1@!&%&*# -> "Internal Server Error" 1@!&%&*! -> "Internal Server Error" | T5: 46133 | U5: Miftha
A6: =ROW(A5) -> 5 | B6: Sprint 5.1 | C6: TC ID - 10 | D6: https://snpgroup.atlassian.net/browse/SPPAT-1724 | E6: As an Global Admin, and Super Admin I can view the product industry list so that I can manage and monitor all available master data efficiently | F6: Global Admin | G6: Web CMS | H6: Global admin can view list of button elipsis on Action Column | I6: * Already login as Global Admin * Already on Product Industry page | J6: * Click kebab menu on Action Column | L6: * Show 2 buttons, there are Edit & Delete on kebab menu | M6: Positive | N6: High | O6: Normal | P6: Medium | Q6: Functional | R6: Passed | T6: 46133 | U6: Miftha
A7: =ROW(A6) -> 6 | B7: Sprint 5.1 | C7: TC ID - 11 | D7: https://snpgroup.atlassian.net/browse/SPPAT-1724 | E7: As an Global Admin, and Super Admin I can view the product industry list so that I can manage and monitor all available master data efficiently | F7: Global Admin | G7: Web CMS | H7: Global Admin can filter with result data not found | I7: * Already login as Global Admin * Already on Product Industry page | J7: * Click filter dropdown beside search column * Select the option based on list | K7: Data on list has been deleted before | L7: * Open the dropdown and show the list on dropdown * Success selected option and show result data not found | M7: Negative | N7: Medium | O7: Normal | P7: Medium | Q7: Functional | R7: Passed | T7: 46133 | U7: Miftha
A8: =ROW(A7) -> 7 | B8: Sprint 5.1 | C8: TC ID - 12 | D8: https://snpgroup.atlassian.net/browse/SPPAT-1725 | E8: As an Global Admin and Super Admin, I can create Industries, Categories, and Sub-Categories data on the form field page when the data I am searching for is not found | F8: Global Admin | G8: Web CMS | H8: Global Admin can view and select list dropdown data "Industry, Category, Sub Category" that has been added from system (BE) on Product Industry page | I8: * User is already login as Global Admin and accessed "Product Industry" menu * Makesure system already added data "Industry, Category, Sub Category" | J8: * Click button "Create Product Industry +" * Click dropdown "Industry" * Select one of list dropdown "Industry" * Click dropdown "Category" * Select one of list dropdown "Category" * Click dropdown "Sub Category" * Select one of list dropdown "Sub Category" | K8: * - * - * ex: Food & Beverages * - * ex: Asian Food * - * ex: Main Course | L8: * Successfully display pop-up "Create Product Industry". On the pop-up display enable dropdown "Industry" (mandatory field), disable dropdown "Category" (mandatory field), disable dropdown "Sub Category" (mandatory field), textarea Product Example (non mandatory). * Successfully display list Industry from system with search bar * Successfully selected list dropdown "Industry", then display dropdown "Category" enable. * Successfully display list Category from system with search bar * Successfully selected list dropdown "Category", then display dropdown "Sub Category" enable. * Successfully display list Sub Category from system * Successfully selected list dropdown "Sub Category" | M8: Positive | N8: Medium | O8: Major | P8: Medium | Q8: Functional
A9: =ROW(A8) -> 8 | B9: Sprint 5.1 | C9: TC ID - 13 | D9: https://snpgroup.atlassian.net/browse/SPPAT-1725 | E9: As an Global Admin and Super Admin, I can create Industries, Categories, and Sub-Categories data on the form field page when the data I am searching for is not found | F9: Global Admin | G9: Web CMS | H9: Global Admin can search data Product Industry only 3 character "Industry, Category, Sub Category" using existing data from system | I9: * User is already login as Global Admin and accessed "Product Industry" menu * Makesure system already added data "Industry, Category, Sub Category" | J9: * Click button "Create Product Industry +" * Click dropdown "Industry" * Type on search bar "Industry" with 3 char * Press "Enter" on keyboard * Select one of list dropdown "Industry" * Click dropdown "Category" * Type on search bar "Category" with 3 char * Press "Enter" on keyboard * Select one of list dropdown "Category" * Click dropdown "Sub Category" * Type on search bar "Category" with 3 char * Press "Enter" on keyboard * Select one of list dropdown "Sub Category" | K9: * - * - * ex: Foo * - * ex: Food & Beverages * - * ex: Asi * - * ex: Asian Food * - * ex: Mai * - * ex: Main Course | L9: * Successfully display pop-up "Create Product Industry". On the pop-up display enable dropdown "Industry" (mandatory field), disable dropdown "Category" (mandatory field), disable dropdown "Sub Category" (mandatory field), textarea Product Example (non mandatory). * Successfully display list Industry from system with search bar * Successfully type on search bar with 3 char * Successfully display suggestion search based on keyword * Successfully selected list dropdown "Industry", then display dropdown "Industry" enable. * Successfully display list Category from system with search bar * Successfully type on search bar with 3 char * Successfully display suggestion search based on keyword * Successfully selected list dropdown "Category", then display dropdown "Sub Category" enable. * Successfully display list Sub Category from system with search bar * Successfully type on search bar with 3 char * Successfully display suggestion search based on keyword * Successfully selected list dropdown "Sub Category" | M9: Positive | N9: Medium | O9: Major | P9: Medium | Q9: Functional | R9: Passed | T9: 46133 | U9: Miftha
A10: =ROW(A9) -> 9 | B10: Sprint 5.1 | C10: TC ID - 14 | D10: https://snpgroup.atlassian.net/browse/SPPAT-1725 | E10: As an Global Admin and Super Admin, I can create Industries, Categories, and Sub-Categories data on the form field page when the data I am searching for is not found | F10: Global Admin | G10: Web CMS | H10: Global Admin cannot search data Product Industry because system not found the result if search only 3 character "Industry, Category, Sub Category" on Product Industry | I10: * User is already login as Global Admin and accessed "Product Industry" menu * Makesure system already added data "Industry, Category, Sub Category" | J10: * Click button "Create Product Industry +" * Click dropdown "Industry" * Type on search bar "Industry" with 3 char * Press "Enter" on keyboard * Select one of list dropdown "Industry" * Click dropdown "Category" * Type on search bar "Category" with 3 char * Press "Enter" on keyboard * Select one of list dropdown "Category" * Click dropdown "Sub Category" * Type on search bar "Category" with 3 char * Press "Enter" on keyboard * Select one of list dropdown "Sub Category" | K10: * - * - * ex: Foo * - * - * ex: Asi * - * - * - * ex: Mai * - * - | L10: * Successfully display pop-up "Create Product Industry". On the pop-up display enable dropdown "Industry" (mandatory field), disable dropdown "Category" (mandatory field), disable dropdown "Sub Category" (mandatory field), textarea Product Example (non mandatory). * Successfully display list Industry from system with search bar * Successfully type on search bar with 3 char * Successfully display result not found and in the new line display "keyword" and button "+ Add New Data" * Successfully selected list dropdown "Industry", then display dropdown "Industry" enable. * Successfully display list Category from system with search bar * Successfully type on search bar with 3 char * Successfully display result not found and in the new line display "keyword" and button "+ Add New Data" * Successfully selected list dropdown "Category", then display dropdown "Sub Category" enable. * Successfully display list Sub Category from system with search bar * Successfully type on search bar with 3 char * Successfully display result not found and in the new line display "keyword" and button "+ Add New Data" | M10: Negative | N10: Medium | O10: Major | P10: Medium | Q10: Functional | R10: Passed | T10: 46134 | U10: Miftha
A11: =ROW(A10) -> 10 | B11: Sprint 5.1 | C11: TC ID - 15 | D11: https://snpgroup.atlassian.net/browse/SPPAT-1725 | E11: As an Global Admin and Super Admin, I can create Industries, Categories, and Sub-Categories data on the form field page when the data I am searching for is not found | F11: Global Admin | G11: Web CMS | H11: Global Admin cannot search data Product Industry because system not found the result if search more than 3 character "Industry, Category, Sub Category" on Product Industry | I11: * User is already login as Global Admin and accessed "Product Industry" menu * Makesure system already added data "Industry, Category, Sub Category" | J11: * Click button "Create Product Industry +" * Click dropdown "Industry" * Type on search bar "Industry" with more than 3 char * Press "Enter" on keyboard * Select one of list dropdown "Industry" * Click dropdown "Category" * Type on search bar "Category" with more than 3 char * Press "Enter" on keyboard * Select one of list dropdown "Category" * Click dropdown "Sub Category" * Type on search bar "Category" with more than 3 char * Press "Enter" on keyboard | K11: * - * - * ex: Food * - * - * ex: Asia * - * - * - * ex: Main * - * - | L11: * Successfully display pop-up "Create Product Industry". On the pop-up display enable dropdown "Industry" (mandatory field), disable dropdown "Category" (mandatory field), disable dropdown "Sub Category" (mandatory field), textarea Product Example (non mandatory). * Successfully display list Industry from system with search bar * Successfully type on search bar with more than 3 char * Successfully display result not found and in the new line display "keyword" and button "+ Add New Data" * Successfully selected list dropdown "Industry", then display dropdown "Industry" enable. * Successfully display list Category from system with search bar * Successfully type on search bar with more than 3 char * Successfully display result not found and in the new line display "keyword" and button "+ Add New Data" * Successfully selected list dropdown "Category", then display dropdown "Sub Category" enable. * Successfully display list Sub Category from system with search bar * Successfully type on search bar with more than 3 char * Successfully display result not found and in the new line display "keyword" and button "+ Add New Data" | M11: Negative | N11: Medium | O11: Major | P11: Medium | Q11: Functional | R11: Passed | T11: 46134 | U11: Miftha

Sheet PIC Organization
A1: NO | B1: SPRINT | C1: TC_ID | D1: LINK STORY | E1: FEATURE / SUITE | F1: ROLE USER | G1: PLATFORM | H1: TEST CASE | I1: PRECONDITIONS | J1: STEPS | K1: DATA | L1: EXPECTED | M1: BEHAVIOUR | N1: PRIORITY | O1: SEVERITY | P1: COMPLEXITY | Q1: TYPE | R1: ACTUAL RESULT | S1: REMARKS | T1: DATE | U1: PIC TESTER | V1: EVIDENCE SIT | W1: Automate/Manual
A2: =ROW(A1) -> 1 | B2: Sprint 5.1 | C2: TC ID - 222 | D2: https://snpgroup.atlassian.net/browse/SPPAT-1741 | E2: As an Global Admin, Super Admin, PIC Organization, I can view the list of user management data so that I can monitor and manage user information effectively | F2: PIC Organization | G2: Web CMS | H2: PIC Organization click settings button on detail Organization page | I2: * User already login as PIC Organization | J2: * Click "Organization Management" menu * Click 1 of Organization on the list * Click Setting icon * Hoover information icon * Click "Cancel" button | K2: * - * - * - * - * - | L2: * Redirect to Organization Management page * Redirect to detail Organization * Show pup up setting organization * Show information "1 Slot is 1 Minutes set your total slots, and the system multiplies them by your showtimes. Example: Insert 20 Slot x 1 Minutes = 20 Minutes campaign in 1 day" * Close pop up | M2: Positive | N2: Medium | O2: Normal | P2: Medium | Q2: Functional | R2: Passed | T2: 46133 | U2: Meriyan Dwi Prakosa | V2: PIC Org TC ID 222.mp4
A3: =ROW(A2) -> 2 | B3: Sprint 5.1 | C3: TC ID - 223 | D3: https://snpgroup.atlassian.net/browse/SPPAT-1741 | E3: As an Global Admin, Super Admin, PIC Organization, I can view the list of user management data so that I can monitor and manage user information effectively | F3: PIC Organization | G3: Web CMS | H3: PIC Organization do Search based on Name and Email & Filter based on All Role | I3: * User already login as PIC Organization * User already on Organization Management page. * User already on Detail Organization page. | J3: * Search on Search bar * Delete all keyword on search bar * Click "All Status" dropdown filter * Choose 1 dropdown option | K3: * Min 3 Char * - * PIC Organization, content creator, device operator, admin organization * PIC Organization, content creator, device operator, admin organization | L3: * Show search filter ,based on Name and Email name. * Show all Data without any filter * Show dropdown * Show filtered based on Role Dropdown | M3: Positive | N3: Medium | O3: Normal | P3: Medium | Q3: Functional | R3: Passed | T3: 46133 | U3: Meriyan Dwi Prakosa | V3: PIC Org TC ID 223.mp4
A4: =ROW(A3) -> 3 | B4: Sprint 5.1 | C4: TC ID - 224 | D4: https://snpgroup.atlassian.net/browse/SPPAT-1741 | E4: As an Global Admin, Super Admin, PIC Organization, I can view the list of user management data so that I can monitor and manage user information effectively | F4: PIC Organization | G4: Web CMS | H4: PIC Organization click detail organization menu, but no data is displayed yet | I4: * User already login as PIC Organization * There is no data on Detail Organization | J4: * Click "Organization Management" menu | K4: * - | L4: * 'The system will display a message: User empty. No data entry" | M4: Negative | N4: Medium | O4: Normal | P4: Medium | Q4: Functional
A5: =ROW(A4) -> 4 | B5: Sprint 5.1 | C5: TC ID - 225 | D5: https://snpgroup.atlassian.net/browse/SPPAT-1741 | E5: As an Global Admin, Super Admin, PIC Organization, I can view the list of user management data so that I can monitor and manage user information effectively | F5: PIC Organization | G5: Web CMS | H5: PIC Organization click detail organization menu ,and search null data | I5: * User already login as PIC Organization * User already on Detail Organization | J5: * Search null data on searchbar | K5: * - | L5: * 'The system will display a message: 'Data Not Found, Data Empty" | M5: Negative | N5: Medium | O5: Normal | P5: Medium | Q5: Functional | R5: Passed | T5: 46133 | U5: Meriyan Dwi Prakosa | V5: PIC Org TC ID 225.mp4
A6: =ROW(A5) -> 5 | B6: Sprint 5.1 | C6: TC ID - 226 | D6: https://snpgroup.atlassian.net/browse/SPPAT-1748 | E6: As an Global Admin, Super Admin and PIC Organization, I can create new user management data so that I can register and manage user information within the system | F6: PIC Organization | G6: Web CMS | H6: PIC Organization Create user on Organization Management | I6: * PIC Organization already login as PIC Organization * PIC Organization already on Organization Management page * PIC Organization already choose 1 organization of data list | J6: * Click "Create User +" button * Input Fullname * Input Email * Select User Role * Input Password * Input Re-Password * Switch toggle Status User * Hoover pointer to information "i" icon * Click "Create User" button | K6: * - * Char max 254 * Mandatory "@", Char max 254 * Content creator, Device Operator, Admin Organization * Min 8 Char,Max 20 Char, contain at least one uppercase letter, one number, and one special character. * Min 8 Char, Max 20 Char, contain at least one uppercase letter, one number, and one special character. * On/Off * - * - | L6: * Show Create User form * Successfully inputted to textbox * Successfully inputted to textbox * Successfully Choose the dropdown * Successfully inputted to textbox * Successfully inputted to textbox * Successfully installed the toggle status * Show information about the toggle * Successfully created the user and show snackbar "user created successfully" | M6: Positive | N6: High | O6: Major | P6: Medium | Q6: Functional | R6: Passed | T6: 46133 | U6: Meriyan Dwi Prakosa | V6: PIC Org TC ID 226.mp4
A7: =ROW(A6) -> 6 | B7: Sprint 5.1 | C7: TC ID - 227 | D7: https://snpgroup.atlassian.net/browse/SPPAT-1748 | E7: As an Global Admin, Super Admin and PIC Organization, I can create new user management data so that I can register and manage user information within the system | F7: PIC Organization | G7: Web CMS | H7: PIC Organization can't Create user on Organization Management if password and re-password not match | I7: * PIC Organization already login as PIC Organization * PIC Organization already on Organization Management page * PIC Organization already choose 1 organization of data list | J7: * Click "Create User +" button * Input Fullname * Input Email * Select User Role * Input Password * Click eye icon * Input Different Re-Password * Click eye icon | K7: * - * Char max 254 * Mandatory "@", Char max 254 * Content creator, Device Operator, Admin Organization * Min 8 Char,Max 20 Char, contain at least one uppercase letter, one number, and one special character. * - * Min 8 Char,Max 20 Char, contain at least one uppercase letter, one number, and one special character. * - | L7: * Show Create User form * Successfully inputted to textbox * Successfully inputted to textbox * Successfully Choose the dropdown * Successfully inputted to textbox * Show or hide text on textbox * the indicator turns red. * Show or hide text on textbox | M7: Negative | N7: High | O7: Major | P7: Medium | Q7: Functional | R7: Passed | T7: 46133 | U7: Meriyan Dwi Prakosa | V7: PIC Org TC ID 227.mp4
A8: =ROW(A7) -> 7 | B8: Sprint 5.1 | C8: TC ID - 228 | D8: https://snpgroup.atlassian.net/browse/SPPAT-1748 | E8: As an Global Admin, Super Admin and PIC Organization, I can create new user management data so that I can register and manage user information within the system | F8: PIC Organization | G8: Web CMS | H8: PIC Organization can't Create user on Organization Management when the Email already registered | I8: * PIC Organization already login as PIC Organization * PIC Organization already on Organization Management page * PIC Organization already choose 1 organization of data list | J8: * Click "Create User +" button * Input Fullname * Input Email that already registered * Select User Role * Input Password * Input Re-Password * Switch toggle Status User * Click "Create User" button | K8: * - * Char max 254 * Mandatory "@", Char max 254 * Content creator, Device Operator, Admin Organization * Min 8 Char,Max 20 Char, contain at least one uppercase letter, one number, and one special character. * Min 8 Char,Max 20 Char, contain at least one uppercase letter, one number, and one special character. * On/Off * - | L8: * Show Create User form * Successfully inputted to textbox * Successfully inputted to textbox * Successfully Choose the dropdown * Successfully inputted to textbox * Successfully inputted to textbox * Successfully installed the toggle status * System display alert snaclbar information "User with email 'userclient@gmail.com' already exists" | M8: Negative | N8: High | O8: Major | P8: Medium | Q8: Functional | R8: Passed | T8: 46133 | U8: Meriyan Dwi Prakosa | V8: PIC Org TC ID 228.mp4
A9: =ROW(A8) -> 8 | B9: Sprint 5.1 | C9: TC ID - 229 | D9: https://snpgroup.atlassian.net/browse/SPPAT-1748 | E9: As an Global Admin, Super Admin and PIC Organization, I can create new user management data so that I can register and manage user information within the system | F9: PIC Organization | G9: Web CMS | H9: PIC Organization can't Create user on Organization Management when lost connection | I9: * PIC Organization already login as PIC Organization * PIC Organization already on Organization Management page * PIC Organization already choose 1 organization of data list * Not connect to internet | J9: * Click "Create User +" button * Input Fullname * Input Email that already registered * Select User Role * Input Password * Input Re-Password * Switch toggle Status User * Click "Create User" button | K9: * - * Char max 254 * Mandatory "@", Char max 254 * Content creator, Device Operator, Admin Organization * Min 8 Char,Max 20 Char, contain at least one uppercase letter, one number, and one special character. * Min 8 Char,Max 20 Char, contain at least one uppercase letter, one number, and one special character. * On/Off * - | L9: * Show Create User form * Successfully inputted to textbox * Successfully inputted to textbox * Successfully Choose the dropdown * Successfully inputted to textbox * Successfully inputted to textbox * Successfully installed the toggle status * System display alert information "User created failed" | M9: Negative | N9: High | O9: Major | P9: Medium | Q9: Functional | R9: Passed | T9: 46133 | U9: Meriyan Dwi Prakosa | V9: PIC Org TC ID 229.mp4
A10: =ROW(A9) -> 9 | B10: Sprint 5.1 | C10: TC ID - 230 | D10: https://snpgroup.atlassian.net/browse/SPPAT-1748 | E10: As an Global Admin, Super Admin and PIC Organization, I can create new user management data so that I can register and manage user information within the system | F10: PIC Organization | G10: Web CMS | H10: PIC Organization can't Create user on Organization Management when internal server error | I10: * PIC Organization already login as PIC Organization * PIC Organization already on Organization Management page * PIC Organization already choose 1 organization of data list * Server unavailable | J10: * Click "Create User +" button * Input Fullname * Input Email that already registered * Select User Role * Input Password * Input Re-Password * Switch toggle Status User * Click "Create User" button | K10: * - * Char max 254 * Mandatory "@", Char max 254 * Content creator, Device Operator, Admin Organization * Min 8 Char,Max 20 Char, contain at least one uppercase letter, one number, and one special character. * Min 8 Char,Max 20 Char, contain at least one uppercase letter, one number, and one special character. * On/Off * - | L10: * Show Create User form * Successfully inputted to textbox * Successfully inputted to textbox * Successfully Choose the dropdown * Successfully inputted to textbox * Successfully inputted to textbox * Successfully installed the toggle status * System display alert information "User created failed" | M10: Negative | N10: High | O10: Major | P10: Medium | Q10: Functional
A11: =ROW(A10) -> 10 | B11: Sprint 5.1 | C11: TC ID - 231 | D11: https://snpgroup.atlassian.net/browse/SPPAT-1748 | E11: As an Global Admin, Super Admin and PIC Organization, I can create new user management data so that I can register and manage user information within the system | F11: PIC Organization | G11: Web CMS | H11: PIC Organization cannot save the form when it has been closed | I11: * PIC Organization already login as PIC Organization * PIC Organization already on Organization Management page * PIC Organization already choose 1 organization of data list | J11: * Click "Create User +" button * Input Fullname * Input Email * Select User Role * Input Password * Input Re-Password * Switch toggle Status User * Hoover pointer to information "i" icon * Click "Cancel" button * Click "Create User +" button | K11: * - * Char max 254 * Mandatory "@", Char max 254 * Content creator, Device Operator, Admin Organization * Min 8 Char,Max 20 Char, contain at least one uppercase letter, one number, and one special character. * Min 8 Char, Max 20 Char, contain at least one uppercase letter, one number, and one special character. * On/Off * - * - * - | L11: * Show Create User form * Successfully inputted to textbox * Successfully inputted to textbox * Successfully Choose the dropdown * Successfully inputted to textbox * Successfully inputted to textbox * Successfully installed the toggle status * Show information about the toggle * Closed the form * . Show blank Create User form | M11: Negative | N11: High | O11: Major | P11: Medium | Q11: Functional | R11: Passed | T11: 46133 | U11: Meriyan Dwi Prakosa | V11: PIC Org TC ID 231.mp4

Sheet Legend
A1: Filename | B1: This file excel name should be [CRQ number]_[anything]
B2: CRQ number refer to CRQ in Selena/ Remedy, anything free as necessary
B3: sample: CRQ000000407740_VAS Code-Arief Setiawan
A4: sheet Template Test Case | B4: could be rename to group of test case, e.g TC Kartu Halo, TC Modul A, etc
A5: sheet Template Defect | B5: could be rename to group of defect, e.g Defect Kartu Halo, Defect Modul A, etc
A6: sheet Legend | B6: sheet that explain how to read this file
A8: Template Test Case
A9: Plan Execution Date | B9: plan execution date for test case
A10: Test Case | B10: name of the test case, for easy reference
A11: Description Test Case | B11: long description of the test case
A12: System Related | B12: surrounding system
A13: Step | B13: detail step number of a test case
A14: Step Description | B14: description of a step of a test case
A15: Expected Result | B15: expected result of a test case, make it as clear as possible
A16: Actual Execution Date | B16: actual execution date with team testing
A17: Status Test Case | B17: status of this test case, choice: No Run, Hold, Invalid, Passed, Failed
A18: Actual Result | B18: currect result/ final result of a test case
A19: Severity | B19: level severity of a test case, refer to TRA/ Test Strategy of this test CRQ, choice: Critical, High, Medium, Low
A20: Cycle | B20: increasing number to show how many this test case have been reiterate, e.g 1, 2, 3, etc
A21: Notes | B21: additional notes, as necessary
A23: Template Defect
A24: Test Case | B24: leave empty for now, name of the test case, for easy reference, foreign key from test case table
A25: Step | B25: leave empty for now, detail step number of a test case, foreign key from test case table
A26: Severity Defect | B26: priority of the defect, choice: Critical, Very High, High, Medium, Low
A27: Defect Description | B27: description of the defect
A28: Status Defect | B28: status of the defect, choice: New, Open, Deferred, Rejected, Closed
A29: Notes | B29: additional notes, optional
E34: =COUNTIF(#REF!,"Rafif*") +COUNTIF(#REF!,"Rafif*") -> #REF!
